order-book/a1-a2-testcases/intermediate-random-3.in

    # Random doubly threaded test case, periodic full clean to keep order book small
    
2
o
0 S 0 AMZN 5524 10
0 B 1 AMZN 6444 19
0 S 2 AMZN 2883 10
0 B 3 AAPL 7202 19
0 S 4 AAPL 1073 11
0 S 5 GOOG 5905 7
0 S 6 GOOG 7506 4
0 B 7 GOOG 3010 16
0 S 8 GOOG 3280 1
0 S 9 AAPL 3951 5
0 B 10 GOOG 3511 9
0 B 11 GOOG 4965 16
0 B 12 GOOG 6908 9
0 B 13 AAPL 4471 14
0 C 10
0 C 4
0 S 14 AMZN 2199 5
0 B 15 AMZN 2145 17
0 B 16 GOOG 4325 15
0 S 17 AMZN 6595 18
0 B 18 AMZN 5558 4
0 B 19 GOOG 8462 20
0 C 2
0 S 20 GOOG 7117 16
0 B 21 AMZN 8665 4
0 C 1
0 S 22 AMZN 1192 5
0 B 23 GOOG 6325 3
0 C 22
0 B 24 AAPL 3494 3
0 C 13
0 S 25 AAPL 3950 7
0 B 26 AMZN 5300 16
0 C 7
0 C 15
0 B 27 GOOG 6455 3
0 C 9
0 B 28 AAPL 3801 7
0 C 16
0 B 29 AMZN 3172 12
0 C 17
0 S 30 AMZN 1001 17
0 S 31 AMZN 1901 9
0 B 32 AAPL 2705 12
0 C 10
0 S 33 AMZN 8684 17
0 B 34 AAPL 3136 17
0 S 35 AAPL 7417 7
0 S 36 AMZN 7229 8
0 S 37 AMZN 2446 19
0 S 38 AMZN 1114 19
0 C 21
0 B 39 AMZN 3789 3
0 C 17
0 B 40 AAPL 2238 15
0 B 41 AAPL 5317 9
0 C 9
0 B 42 AAPL 2101 5
0 S 43 AAPL 6554 1
0 S 44 GOOG 7637 8
0 S 45 AAPL 7488 19
0 C 7
0 S 46 AAPL 8682 1
0 S 47 AMZN 1373 13
0 C 32
0 B 48 AAPL 8043 15
0 S 49 AAPL 4612 9
0 C 41
0 C 4
0 B 50 GOOG 1411 10
0 S 51 GOOG 6140 8
0 C 25
0 S 52 GOOG 2809 15
0 S 53 GOOG 8702 10
0 C 25
0 C 15
0 C 50
0 C 13
0 S 54 AMZN 4436 3
0 B 55 AAPL 7531 18
0 B 56 GOOG 5477 3
0 C 43
0 S 57 AAPL 1649 20
0 C 15
0 S 58 GOOG 7717 11
0 B 59 AAPL 1170 12
0 B 60 AAPL 4075 20
0 S 61 AMZN 1967 11
0 B 62 GOOG 5950 2
0 B 63 AMZN 7883 5
0 C 1
0 C 63
0 B 64 AMZN 7452 18
0 C 25
0 B 65 AAPL 8582 17
0 S 66 GOOG 7722 20
0 B 67 AMZN 2837 12
0 B 68 GOOG 8283 14
0 S 69 AMZN 3793 19
0 C 69
1 B 70 AAPL 1462 12
1 S 71 GOOG 3632 15
1 C 71
1 S 72 AAPL 2116 3
1 C 72
1 S 73 AAPL 1033 10
1 C 71
1 B 74 GOOG 8615 19
1 B 75 GOOG 1330 11
1 C 73
1 S 76 AAPL 2022 12
1 S 77 AAPL 8522 19
1 S 78 AAPL 2877 12
1 B 79 AMZN 5213 2
1 C 79
1 S 80 GOOG 7830 20
1 B 81 GOOG 3059 10
1 B 82 AAPL 5679 18
1 S 83 AMZN 2461 19
1 S 84 AAPL 3208 16
1 S 85 AMZN 4808 8
1 B 86 AAPL 7324 5
1 B 87 GOOG 1051 16
1 C 85
1 S 88 GOOG 1008 5
1 B 89 AAPL 4125 1
1 B 90 GOOG 3337 18
1 S 91 AAPL 1208 12
1 C 72
1 S 92 AMZN 7599 13
1 S 93 AMZN 8041 6
1 C 90
1 C 85
1 B 94 AAPL 2269 17
1 C 90
1 B 95 AAPL 6334 1
1 S 96 AMZN 5374 20
1 C 92
1 C 71
1 S 97 GOOG 3734 2
1 C 95
1 B 98 AMZN 7366 5
1 C 91
1 S 99 AAPL 6766 10
1 C 88
1 S 100 AAPL 1174 19
1 S 101 GOOG 8133 4
1 B 102 GOOG 6906 4
1 C 73
1 B 103 GOOG 5698 6
1 B 104 GOOG 3262 13
1 C 73
1 S 105 AAPL 8617 7
1 S 106 GOOG 4937 13
1 B 107 AMZN 5638 4
1 S 108 GOOG 5421 4
1 S 109 AAPL 2233 8
1 C 97
1 S 110 GOOG 3811 13
1 C 84
1 B 111 GOOG 5428 10
1 B 112 AAPL 5720 15
1 B 113 GOOG 4838 8
1 S 114 AAPL 3659 18
1 S 115 AAPL 3363 19
1 B 116 AAPL 4906 10
1 S 117 AAPL 1804 16
1 C 104
1 B 118 AMZN 6030 7
1 B 119 GOOG 5505 13
1 C 117
1 B 120 AAPL 5170 10
1 S 121 GOOG 6321 12
1 B 122 GOOG 2780 5
1 C 84
1 B 123 AMZN 6523 7
1 B 124 AMZN 2180 15
1 C 106
1 B 125 AMZN 8470 10
1 C 93
1 S 126 AMZN 3806 13
1 S 127 AMZN 4622 14
1 C 77
1 B 128 GOOG 2300 5
1 S 129 GOOG 1341 3
1 S 130 AAPL 2498 12
1 C 77
1 B 131 GOOG 3117 7
1 B 132 AMZN 4339 6
1 C 118
1 B 133 AMZN 6809 9
1 S 134 AMZN 1062 8
1 B 135 AAPL 5786 18
1 S 136 AMZN 5327 11
1 C 92
1 B 137 GOOG 7285 3
1 C 104
1 B 138 AAPL 8822 13
1 B 139 AAPL 4677 16
1 S 140 AMZN 2691 6
.
0 C 0
0 C 3
0 C 5
0 C 6
0 C 8
0 C 11
0 C 12
0 C 14
0 C 18
0 C 19
0 C 20
0 C 23
0 C 24
0 C 26
0 C 27
0 C 28
0 C 29
0 C 30
0 C 31
0 C 33
0 C 34
0 C 35
0 C 36
0 C 37
0 C 38
0 C 39
0 C 40
0 C 42
0 C 44
0 C 45
0 C 46
0 C 47
0 C 48
0 C 49
0 C 51
0 C 52
0 C 53
0 C 54
0 C 55
0 C 56
0 C 57
0 C 58
0 C 59
0 C 60
0 C 61
0 C 62
0 C 64
0 C 65
0 C 66
0 C 67
0 C 68
1 C 70
1 C 74
1 C 75
1 C 76
1 C 78
1 C 80
1 C 81
1 C 82
1 C 83
1 C 86
1 C 87
1 C 89
1 C 94
1 C 96
1 C 98
1 C 99
1 C 100
1 C 101
1 C 102
1 C 103
1 C 105
1 C 107
1 C 108
1 C 109
1 C 110
1 C 111
1 C 112
1 C 113
1 C 114
1 C 115
1 C 116
1 C 119
1 C 120
1 C 121
1 C 122
1 C 123
1 C 124
1 C 125
1 C 126
1 C 127
1 C 128
1 C 129
1 C 130
1 C 131
1 C 132
1 C 133
1 C 134
1 C 135
1 C 136
1 C 137
1 C 138
1 C 139
1 C 140
0 B 141 GOOG 5298 17
0 C 141
0 S 142 AAPL 6799 16
0 S 143 AAPL 7144 2
0 C 142
0 S 144 AAPL 2493 16
0 C 144
0 B 145 GOOG 2323 19
0 B 146 AAPL 8651 10
0 C 141
0 C 141
0 B 147 AMZN 2284 20
0 S 148 AAPL 4788 8
0 B 149 GOOG 4222 10
0 B 150 AAPL 6115 10
0 S 151 AAPL 6428 3
0 S 152 AMZN 4743 16
0 S 153 AMZN 7060 11
0 B 154 AMZN 1488 10
0 S 155 AMZN 5934 7
0 C 154
0 C 145
0 C 146
0 B 156 AAPL 2998 6
0 S 157 AMZN 8668 3
0 C 150
0 C 156
0 B 158 AAPL 8568 20
0 B 159 AAPL 1411 14
0 S 160 AMZN 1537 10
0 C 155
0 C 158
0 S 161 AMZN 4690 11
0 C 152
0 C 143
0 C 160
0 C 159
0 S 162 GOOG 4382 10
0 B 163 AMZN 8110 18
0 B 164 AAPL 4305 1
0 S 165 AMZN 4091 6
0 C 156
0 B 166 AMZN 4402 13
0 B 167 GOOG 8033 6
0 C 158
0 S 168 AMZN 5513 11
0 C 157
0 C 143
0 S 169 AMZN 1940 3
0 S 170 GOOG 1203 7
0 S 171 AMZN 7124 7
0 B 172 GOOG 3251 8
0 S 173 AMZN 2632 5
0 C 159
0 B 174 AAPL 1974 3
0 S 175 GOOG 5591 20
0 C 146
0 B 176 GOOG 6038 18
0 C 172
0 B 177 AMZN 2684 5
0 B 178 GOOG 1308 13
0 S 179 AMZN 5753 17
0 S 180 AAPL 8226 18
0 B 181 GOOG 1915 1
0 B 182 GOOG 6013 16
0 C 144
0 S 183 AMZN 7648 7
0 S 184 AAPL 7182 8
0 C 167
0 S 185 GOOG 7926 8
0 S 186 AMZN 8855 3
0 B 187 GOOG 5944 20
0 C 151
0 S 188 GOOG 7797 1
0 S 189 AMZN 8367 14
0 S 190 GOOG 7896 20
0 S 191 GOOG 5389 20
0 B 192 AMZN 7645 20
0 C 145
0 C 146
0 S 193 AAPL 5133 10
0 S 194 GOOG 7425 17
0 B 195 AMZN 4462 12
0 B 196 GOOG 4752 1
0 B 197 AMZN 1714 14
0 S 198 AMZN 1853 13
0 C 152
0 B 199 AMZN 6223 18
0 B 200 GOOG 7296 15
0 S 201 GOOG 8207 2
0 B 202 GOOG 1626 8
0 B 203 GOOG 1603 2
0 B 204 AAPL 1316 13
0 C 169
0 S 205 AAPL 4550 19
0 S 206 AAPL 7753 8
0 S 207 GOOG 8595 16
0 S 208 AAPL 1735 12
0 S 209 AMZN 5079 10
0 B 210 AAPL 7311 18
1 B 211 AMZN 2890 6
1 S 212 AMZN 7708 12
1 S 213 AMZN 1932 9
1 S 214 AAPL 7342 20
1 S 215 AAPL 3100 19
1 B 216 AMZN 3905 11
1 C 211
1 B 217 GOOG 1736 15
1 S 218 GOOG 3701 1
1 C 218
1 B 219 GOOG 6813 13
1 B 220 AMZN 2410 16
1 S 221 AAPL 5316 2
1 C 212
1 B 222 AMZN 2976 5
1 C 221
1 B 223 AMZN 3951 9
1 B 224 AMZN 5191 4
1 C 212
1 S 225 AAPL 2938 12
1 C 225
1 C 212
1 S 226 GOOG 7289 14
1 B 227 AAPL 3457 15
1 B 228 GOOG 2281 17
1 S 229 AAPL 7795 18
1 S 230 AAPL 8643 14
1 C 211
1 C 220
1 B 231 AMZN 1044 10
1 C 217
1 S 232 AAPL 5859 18
1 S 233 AAPL 2109 5
1 C 221
1 B 234 GOOG 4665 20
1 C 217
1 C 215
1 B 235 AAPL 1889 8
1 S 236 GOOG 2671 11
1 B 237 AAPL 3421 4
1 B 238 AMZN 7660 19
1 S 239 AAPL 5137 17
1 B 240 GOOG 5588 2
1 C 231
1 S 241 GOOG 6875 8
1 B 242 GOOG 4377 9
1 C 224
1 S 243 GOOG 6300 15
1 B 244 AMZN 2549 4
1 S 245 AMZN 5140 16
1 B 246 AMZN 2678 4
1 C 212
1 C 216
1 B 247 AMZN 4411 2
1 B 248 AMZN 2194 1
1 S 249 GOOG 1899 13
1 C 216
1 B 250 AAPL 8018 11
1 B 251 AMZN 1761 7
1 B 252 GOOG 3567 4
1 C 239
1 C 231
1 B 253 AMZN 5875 17
1 C 243
1 S 254 GOOG 8043 19
1 S 255 GOOG 3518 13
1 S 256 AAPL 1364 3
1 C 218
1 S 257 AMZN 6189 13
1 C 242
1 B 258 GOOG 6862 5
1 S 259 AMZN 5200 11
1 C 252
1 C 242
1 B 260 AMZN 7482 9
1 S 261 GOOG 6298 6
1 C 243
1 B 262 GOOG 1745 10
1 C 251
1 B 263 AAPL 2441 12
1 B 264 GOOG 6437 6
1 B 265 GOOG 3170 3
1 B 266 GOOG 6503 1
1 B 267 AAPL 8831 20
1 B 268 AMZN 1506 12
1 B 269 AMZN 5283 20
1 C 244
1 B 270 GOOG 1081 11
1 B 271 AAPL 6030 10
1 C 218
1 S 272 AMZN 1757 13
1 S 273 AAPL 6314 18
1 B 274 AMZN 4757 11
1 C 212
1 C 264
1 S 275 AAPL 6441 13
1 B 276 AMZN 2508 11
1 C 234
1 C 214
1 C 214
.
0 C 147
0 C 148
0 C 149
0 C 153
0 C 161
0 C 162
0 C 163
0 C 164
0 C 165
0 C 166
0 C 168
0 C 170
0 C 171
0 C 173
0 C 174
0 C 175
0 C 176
0 C 177
0 C 178
0 C 179
0 C 180
0 C 181
0 C 182
0 C 183
0 C 184
0 C 185
0 C 186
0 C 187
0 C 188
0 C 189
0 C 190
0 C 191
0 C 192
0 C 193
0 C 194
0 C 195
0 C 196
0 C 197
0 C 198
0 C 199
0 C 200
0 C 201
0 C 202
0 C 203
0 C 204
0 C 205
0 C 206
0 C 207
0 C 208
0 C 209
0 C 210
1 C 213
1 C 219
1 C 222
1 C 223
1 C 226
1 C 227
1 C 228
1 C 229
1 C 230
1 C 232
1 C 233
1 C 235
1 C 236
1 C 237
1 C 238
1 C 240
1 C 241
1 C 245
1 C 246
1 C 247
1 C 248
1 C 249
1 C 250
1 C 253
1 C 254
1 C 255
1 C 256
1 C 257
