order-book/tests/test2.out
B 101 GOOG 2705 30 T1
B 102 AAPL 150 50 T2
E 101 103 103 2705 20 T3
S 104 AAPL 151 30 T4
B 105 MSFT 300 100 T5
E 105 106 106 300 40 T6
X 101 A T7
B 107 TSLA 700 10 T8
E 107 108 108 700 5 T9
B 109 GOOG 2706 25 T10
E 109 110 110 2706 25 T11
S 110 GOOG 2706 5 T12
B 111 AAPL 150 20 T13
E 102 112 112 150 20 T14
X 130 R T15
B 113 AMZN 3300 10 T16
S 114 AMZN 3301 5 T17
B 115 TSLA 700 15 T18
E 107 116 116 700 5 T19
E 115 116 116 700 5 T20
B 117 GOOG 2705 50 T21
E 117 118 118 2705 40 T22
